[2025-05-19T01:43:03.785+0000] {taskinstance.py:1159} INFO - Dependencies all met for dep_context=non-requeueable deps ti=<TaskInstance: pipeline_dados.upload_raw_data_to_bronze manual__2025-05-19T01:42:55.122288+00:00 [queued]>
[2025-05-19T01:43:03.800+0000] {taskinstance.py:1159} INFO - Dependencies all met for dep_context=requeueable deps ti=<TaskInstance: pipeline_dados.upload_raw_data_to_bronze manual__2025-05-19T01:42:55.122288+00:00 [queued]>
[2025-05-19T01:43:03.800+0000] {taskinstance.py:1361} INFO - Starting attempt 1 of 2
[2025-05-19T01:43:03.989+0000] {taskinstance.py:1382} INFO - Executing <Task(PythonOperator): upload_raw_data_to_bronze> on 2025-05-19 01:42:55.122288+00:00
[2025-05-19T01:43:03.999+0000] {standard_task_runner.py:57} INFO - Started process 82 to run task
[2025-05-19T01:43:04.010+0000] {standard_task_runner.py:84} INFO - Running: ['airflow', 'tasks', 'run', 'pipeline_dados', 'upload_raw_data_to_bronze', 'manual__2025-05-19T01:42:55.122288+00:00', '--job-id', '14', '--raw', '--subdir', 'DAGS_FOLDER/dag_pipeline_dados.py', '--cfg-path', '/tmp/tmpziyfdc4z']
[2025-05-19T01:43:04.013+0000] {standard_task_runner.py:85} INFO - Job 14: Subtask upload_raw_data_to_bronze
[2025-05-19T01:43:04.455+0000] {task_command.py:415} INFO - Running <TaskInstance: pipeline_dados.upload_raw_data_to_bronze manual__2025-05-19T01:42:55.122288+00:00 [running]> on host d9fbdfb579ba
[2025-05-19T01:43:06.491+0000] {taskinstance.py:1660} INFO - Exporting env vars: AIRFLOW_CTX_DAG_OWNER='airflow' AIRFLOW_CTX_DAG_ID='pipeline_dados' AIRFLOW_CTX_TASK_ID='upload_raw_data_to_bronze' AIRFLOW_CTX_EXECUTION_DATE='2025-05-19T01:42:55.122288+00:00' AIRFLOW_CTX_TRY_NUMBER='1' AIRFLOW_CTX_DAG_RUN_ID='manual__2025-05-19T01:42:55.122288+00:00'
[2025-05-19T01:43:06.494+0000] {logging_mixin.py:151} INFO - Erro ao carregar os dados brutos: [Errno 2] No such file or directory: '/opt/airflow/data/raw/raw_data.csv'
[2025-05-19T01:43:06.495+0000] {taskinstance.py:1943} ERROR - Task failed with exception
Traceback (most recent call last):
  File "/home/airflow/.local/lib/python3.8/site-packages/airflow/operators/python.py", line 192, in execute
    return_value = self.execute_callable()
  File "/home/airflow/.local/lib/python3.8/site-packages/airflow/operators/python.py", line 209, in execute_callable
    return self.python_callable(*self.op_args, **self.op_kwargs)
  File "/opt/airflow/dags/dag_pipeline_dados.py", line 36, in upload_raw_data_to_bronze
    df = pd.read_csv(input_path)
  File "/home/airflow/.local/lib/python3.8/site-packages/pandas/io/parsers/readers.py", line 912, in read_csv
    return _read(filepath_or_buffer, kwds)
  File "/home/airflow/.local/lib/python3.8/site-packages/pandas/io/parsers/readers.py", line 577, in _read
    parser = TextFileReader(filepath_or_buffer, **kwds)
  File "/home/airflow/.local/lib/python3.8/site-packages/pandas/io/parsers/readers.py", line 1407, in __init__
    self._engine = self._make_engine(f, self.engine)
  File "/home/airflow/.local/lib/python3.8/site-packages/pandas/io/parsers/readers.py", line 1661, in _make_engine
    self.handles = get_handle(
  File "/home/airflow/.local/lib/python3.8/site-packages/pandas/io/common.py", line 859, in get_handle
    handle = open(
FileNotFoundError: [Errno 2] No such file or directory: '/opt/airflow/data/raw/raw_data.csv'
[2025-05-19T01:43:06.533+0000] {taskinstance.py:1400} INFO - Marking task as UP_FOR_RETRY. dag_id=pipeline_dados, task_id=upload_raw_data_to_bronze, execution_date=20250519T014255, start_date=20250519T014303, end_date=20250519T014306
[2025-05-19T01:43:06.762+0000] {standard_task_runner.py:104} ERROR - Failed to execute job 14 for task upload_raw_data_to_bronze ([Errno 2] No such file or directory: '/opt/airflow/data/raw/raw_data.csv'; 82)
[2025-05-19T01:43:06.801+0000] {local_task_job_runner.py:228} INFO - Task exited with return code 1
[2025-05-19T01:43:06.841+0000] {taskinstance.py:2784} INFO - 0 downstream tasks scheduled from follow-on schedule check
